<?xml version="1.0"?>
<!-- 

  ROS urdf definition of TEO arm using xacro

  RoboticsLab, University Carlos III of Madrid

  Joint names and properties are according to REP-120:
  Coordinate Frames for Humanoids Robots

  http://ros.org/reps/rep-0120.html

-->


<robot name="teo" xmlns:xacro="http://ros.org/wiki/xacro">

<!-- *** TEO ARM PARAMETERS -->

<!-- Link lengths (meters)-->
	<!--xacro:property name="chest_link1" value="0.0" />
	<xacro:property name="chest_link2" value="0.245" /-->
	<xacro:property name="arm_link1" value="0.340" /> <!-- Clavicle -->
	<xacro:property name="arm_link2" value="0.32901" /> <!-- Humerus -->
	<xacro:property name="arm_link3" value="0.202" /> <!-- Ulna -->

<!-- Minimum angles (degrees) -->
	<xacro:property name="shoulder_pitch_lower" value="${-180 * deg_to_rad}" />
	<xacro:property name="shoulder_roll_lower" value="${-45 * deg_to_rad}" />
	<xacro:property name="shoulder_yaw_lower" value="${-60 * deg_to_rad}" />
	<xacro:property name="elbow_pitch_lower" value="${-100 * deg_to_rad}" />
	<xacro:property name="wrist_yaw_lower" value="${-105 * deg_to_rad}" />
	<xacro:property name="wrist_pitch_lower" value="${-40 * deg_to_rad}" />

<!-- Maximum angles (degrees) -->
	<xacro:property name="shoulder_pitch_upper" value="${180 * deg_to_rad}" />
	<xacro:property name="shoulder_roll_upper" value="${120 * deg_to_rad}" />
	<xacro:property name="shoulder_yaw_upper" value="${60 * deg_to_rad}" />
	<xacro:property name="elbow_pitch_upper" value="${100 * deg_to_rad}" />
	<xacro:property name="wrist_yaw_upper" value="${105 * deg_to_rad}" />
	<xacro:property name="wrist_pitch_upper" value="${55 * deg_to_rad}" />

<!-- Effort limit of the angles -->
	<xacro:property name="shoulder_pitch_effort" value="30.0" />
	<xacro:property name="shoulder_roll_effort" value="30.0" />
	<xacro:property name="shoulder_yaw_effort" value="30.0" />
	<xacro:property name="elbow_pitch_effort" value="30.0" />
	<xacro:property name="wrist_yaw_effort" value="30.0" />
	<xacro:property name="wrist_pitch_effort" value="30.0" />


<!-- Velocity limit of the angles-->
	<xacro:property name="shoulder_pitch_velocity" value="3.0" />
	<xacro:property name="shoulder_roll_velocity" value="3.0" />
	<xacro:property name="shoulder_yaw_velocity" value="3.0" />
	<xacro:property name="elbow_pitch_velocity" value="3.0" />
	<xacro:property name="wrist_yaw_velocity" value="3.0" />
	<xacro:property name="wrist_pitch_velocity" value="3.0" />

<!-- Damping of the joints-->
	<xacro:property name="shoulder_pitch_damping" value="0.0" />
	<xacro:property name="shoulder_roll_damping" value="0.0" />
	<xacro:property name="shoulder_yaw_damping" value="0.0" />
	<xacro:property name="elbow_pitch_damping" value="0.0" />
	<xacro:property name="wrist_yaw_damping" value="0.0" />
	<xacro:property name="wrist_pitch_damping" value="0.0" />

<!-- Friction of the joints--> <!-- IT'S NOT USED IN GAZEBO-->
	<xacro:property name="shoulder_pitch_friction" value="0.0" />
	<xacro:property name="shoulder_roll_friction" value="0.0" />
	<xacro:property name="shoulder_yaw_friction" value="0.0" />
	<xacro:property name="elbow_pitch_friction" value="0.0" />
	<xacro:property name="wrist_yaw_friction" value="0.0" />
	<xacro:property name="wrist_pitch_friction" value="0.0" />

<!-- Joint reductions-->
	<xacro:property name="shoulder_pitch_reduction" value="1.0" />
	<xacro:property name="shoulder_roll_reduction" value="1.0" />
	<xacro:property name="shoulder_yaw_reduction" value="1.0" />
	<xacro:property name="elbow_pitch_reduction" value="1.0" />
	<xacro:property name="wrist_yaw_reduction" value="1.0" />
	<xacro:property name="wrist_pitch_reduction" value="1.0" />


<!-- *** TEO ARM MACROS -->

  <!-- Links -->
  <xacro:macro name="arms_links" params="side reflect">
    <link name="${side}_shoulder_pitch_link">
      <inertial>
        <origin xyz="0.0 ${reflect*0.0} 0.0" rpy="0 0 0"/>
        <mass value="0.005"/>
        <!-- <inertia ixx="1.000" ixy="0.000" ixz="0.000" iyy="1.000" iyz="0.000" izz="1.000" />-->
	<inertia ixx="0.059121e-5" ixy="0.000603e-5" ixz="0.000103e-5" iyy="0.024956e-5" iyz="0.005131e-5" izz="0.050653e-5" /> 
	<!-- Mass scaled-->
	<!-- <inertia ixx="0.295605e-5" ixy="0.003015e-5" ixz="0.000515e-5" iyy="0.12478e-5" iyz="0.025655e-5" izz="0.253265e-5" /> -->
      </inertial>
      <xacro:insert_visualization_shoulder_pitch side="${side}" reflect="${reflect}"/>
    </link>
    <link name="${side}_shoulder_roll_link">
      <inertial>
        <origin xyz="0.0 ${reflect*0.0} 0.0" rpy="0 0 0"/>
        <mass value="0.005"/>
        <!-- <inertia
				  ixx="1.000" ixy="0.000" ixz="0.000"
					iyy="1.000" iyz="0.000"
					izz="1.000" /> -->
	<inertia ixx="0.018036e-5" ixy="-0.000773e-5" ixz="0.002406e-5" iyy="0.024499e-5" iyz="0.001826e-5" izz="0.013143e-5" />
	<!-- Mass escaled -->
	<!-- <inertia ixx="0.09018e-5" ixy="-0.003865e-5" ixz="0.01203e-5" iyy="0.122495e-5" iyz="0.00913e-5" izz="0.065715e-5" /> -->
      </inertial>
      <xacro:insert_visualization_shoulder_roll side="${side}" reflect="${reflect}"/>
    </link>
    <link name="${side}_shoulder_yaw_link">
      <inertial>
        <origin xyz="0.0 ${reflect*0.0} 0.0" rpy="0 0 0"/>
        <mass value="1.750625"/>
        <!-- <inertia
				  ixx="7.000e-3" ixy="2.148e-5" ixz="3.931e-5"
					iyy="7.000e-3" iyz="1.558e-5"
					izz="8.195e-4" /> -->
	<inertia ixx="0.227681e-2" ixy="0.0" ixz="0.0" iyy="0.224821e-2" iyz="-0.000684e-2" izz="0.032283e-2" /> 
	<!-- Mass scaled -->
	<!-- <inertia ixx="0.39844175e-2" ixy="0.0" ixz="0.0" iyy="0.39343675e-2" iyz="-0.001197e-2" izz="0.05649525e-2" /> -->
      </inertial>
      <xacro:insert_visualization_shoulder_yaw side="${side}" reflect="${reflect}"/>
    </link>
    <link name="${side}_elbow_pitch_link">
      <inertial>
        <origin xyz="0.0 ${reflect*0.0} 0.0" rpy="0 0 0"/>
        <mass value="2.396"/>
        <!-- <inertia
				  ixx="3.000e-3" ixy="9.570e-4" ixz="6.522e-6"
					iyy="3.000e-3" iyz="3.778e-5"
					izz="3.000e-3" /> -->
	<inertia ixx="0.059390e-2" ixy="0.0" ixz="0.0" iyy="0.060871e-2" iyz="-0.0" izz="0.023257e-2" /> -->
	<!-- Mass scaled-->
	<!-- <inertia ixx="0.14229844e-2" ixy="0.0" ixz="0.0" iyy="0.145846916e-2" iyz="-0.0" izz="0.055723772e-2" />-->
      </inertial>
      <xacro:insert_visualization_elbow_pitch side="${side}" reflect="${reflect}"/>
    </link>
    <link name="${side}_wrist_yaw_link">
      <inertial>
        <origin xyz="-0.004657 ${reflect*-0.001356} 0.035884" rpy="0 0 0"/>
        <mass value="0.005"/>
        <!-- <inertia
				  ixx="1.000" ixy="0.000" ixz="0.000"
					iyy="1.000" iyz="0.000"
					izz="1.000" /> -->
	<!--<inertia ixx="5*0.004543e-8" ixy="5*0.000068e-8" ixz="5*0.000070e-8" iyy="5*0.003969e-8" iyz="5*-0.000074e-8" izz="5*0.002118e-8" /> -->
	<inertia ixx="0.004543e-5" ixy="0.000068e-5" ixz="0.000070e-5" iyy="0.003969e-5" iyz="-0.000074e-5" izz="0.002118e-5" />
	<!-- Mass scaled -->
	<!-- <inertia ixx="0.022715e-5" ixy="0.00034e-5" ixz="0.00035e-5" iyy="0.019845e-5" iyz="-0.00037e-5" izz="0.01059e-5" /> -->
      </inertial>
      <xacro:insert_visualization_wrist_yaw side="${side}" reflect="${reflect}"/>
    </link>
    <link name="${side}_wrist_pitch_link">
      <inertial>
        <origin xyz="-0.002438 ${reflect*0.004651} -0.044838" rpy="0 0 0"/>
        <mass value="0.3"/>
        <!-- <inertia
				  ixx="3.400e-4" ixy="0.000" ixz="0.000"
					iyy="3.125e-4" iyz="0.000"
					izz="1.525e-4" />-->
	<!--<inertia ixx="0.007270e-2" ixy="0.0" ixz="0.0" iyy="0.007586e-2" iyz="0.000055e-2" izz="0.003248e-2" /> -->
	<inertia ixx="-0.008337e-3" ixy="0.003468e-3" ixz="-0.005567e-3" iyy="-0.013674e-3" iyz="0.005108e-3" izz="0.005142e-3" />
	<!-- Mass scaled -->
	<!-- <inertia ixx="-0.02502e-2" ixy="0.010401e-2" ixz="-0.016707e-2" iyy="-0.041034e-2" iyz="0.01146e-2" izz="0.015405e-2" /> -->
      </inertial>
      <xacro:insert_visualization_wrist_pitch side="${side}" reflect="${reflect}"/>
    </link>

  </xacro:macro>


  <!-- Joints -->
  <xacro:macro name="arms_joints" params="side reflect effortTransmission velocityTransmission positionTransmission">
    <joint name="${side}_shoulder_pitch" type="revolute">
      <parent link="waist_pitch_link"/>
      <child link="${side}_shoulder_pitch_link"/>
      <origin xyz="-${chest_link1} ${reflect*arm_link1} ${chest_link2+torso_link2}" rpy="0 0 0"/>
      <axis xyz="0 1 0"/>
      <limit velocity="${shoulder_pitch_velocity}" effort="${shoulder_pitch_effort}" lower="${shoulder_pitch_lower}" upper="${shoulder_pitch_upper}"/>
    </joint> 
    <joint name="${side}_shoulder_roll" type="revolute">
      <parent link="${side}_shoulder_pitch_link"/>
      <child link="${side}_shoulder_roll_link"/>
      <origin xyz="0 0 0" rpy="0 0 0"/>
      <axis xyz="1 0 0"/>
      <limit velocity="${shoulder_roll_velocity}" effort="${shoulder_roll_effort}" lower="${shoulder_roll_lower}" upper="${shoulder_roll_upper}"/>
    </joint> 
    <joint name="${side}_shoulder_yaw" type="revolute">
      <parent link="${side}_shoulder_roll_link"/>
      <child link="${side}_shoulder_yaw_link"/>
      <origin xyz="0 0 0" rpy="0 0 0"/>
      <axis xyz="0 0 1"/>
      <limit velocity="${shoulder_yaw_velocity}" effort="${shoulder_yaw_effort}" lower="${shoulder_yaw_lower}" upper="${shoulder_yaw_upper}"/>
    </joint>
    <joint name="${side}_elbow_pitch" type="revolute">
      <parent link="${side}_shoulder_yaw_link"/>
      <child link="${side}_elbow_pitch_link"/>
      <origin xyz="0 0 -${arm_link2}" rpy="0 0 0"/>
      <axis xyz="0 1 0"/>
      <limit velocity="${elbow_pitch_velocity}" effort="${elbow_pitch_effort}" lower="${elbow_pitch_lower}" upper="${elbow_pitch_upper}"/>
    </joint> 
    <joint name="${side}_wrist_yaw" type="revolute">
      <parent link="${side}_elbow_pitch_link"/>
      <child link="${side}_wrist_yaw_link"/>
      <origin xyz="0 0 -${arm_link3}" rpy="0 0 0"/>
      <axis xyz="0 0 1"/>
      <limit velocity="${wrist_yaw_velocity}" effort="${wrist_yaw_effort}" lower="${wrist_yaw_lower}" upper="${wrist_yaw_upper}"/>
    </joint> 
    <joint name="${side}_wrist_pitch" type="revolute">
      <parent link="${side}_wrist_yaw_link"/>
      <child link="${side}_wrist_pitch_link"/>
      <origin xyz="0 0 0" rpy="0 0 0"/>
      <axis xyz="0 1 0"/>
      <limit velocity="${wrist_pitch_velocity}" effort="${wrist_pitch_effort}" lower="${wrist_pitch_lower}" upper="${wrist_pitch_upper}"/>
    </joint>  

    <xacro:limb_joint_simple_transmission name="shoulder" side="${side}" axis="pitch" reduction="${shoulder_pitch_reduction}" effortTransmission="${effortTransmission}" velocityTransmission="${velocityTransmission}" positionTransmission="${positionTransmission}"/>
    <xacro:limb_joint_simple_transmission name="shoulder" side="${side}" axis="roll" reduction="${shoulder_roll_reduction}" effortTransmission="${effortTransmission}" velocityTransmission="${velocityTransmission}" positionTransmission="${positionTransmission}"/>
    <xacro:limb_joint_simple_transmission name="shoulder" side="${side}" axis="yaw" reduction="${shoulder_yaw_reduction}" effortTransmission="${effortTransmission}" velocityTransmission="${velocityTransmission}" positionTransmission="${positionTransmission}"/>
    <xacro:limb_joint_simple_transmission name="elbow" side="${side}" axis="pitch" reduction="${elbow_pitch_reduction}" effortTransmission="${effortTransmission}" velocityTransmission="${velocityTransmission}" positionTransmission="${positionTransmission}"/>
    <xacro:limb_joint_simple_transmission name="wrist" side="${side}" axis="yaw" reduction="${wrist_yaw_reduction}" effortTransmission="${effortTransmission}" velocityTransmission="${velocityTransmission}" positionTransmission="${positionTransmission}"/>
    <xacro:limb_joint_simple_transmission name="wrist" side="${side}" axis="pitch" reduction="${wrist_pitch_reduction}" effortTransmission="${effortTransmission}" velocityTransmission="${velocityTransmission}" positionTransmission="${positionTransmission}"/>

  </xacro:macro>

  <xacro:arms_links side="l" reflect="1"/>
  <xacro:arms_links side="r" reflect="-1"/>  
  <xacro:arms_joints side="l" reflect="1" effortTransmission="1" velocityTransmission="0" positionTransmission="0"/>
  <xacro:arms_joints side="r" reflect="-1" effortTransmission="1" velocityTransmission="0" positionTransmission="0"/> 

</robot>
