<?xml version="1.0" ?>
<!-- =================================================================================== -->
<!-- |    This document was autogenerated by xacro from teo_humanoid.urdf.xacro        | -->
<!-- |    EDITING THIS FILE BY HAND IS NOT RECOMMENDED                                 | -->
<!-- =================================================================================== -->
<!--
  ROS urdf definition of TEO humanoid robot
  
  Author: Domingo Esteban
  RoboticsLab, Universidad Carlos III de Madrid
  
  This file loads TEO model with a basic visualization.

  If you want to convert this xacro file into an urdf file:
  $ rosrun xacro xacro.py teo_humanoid_simple_vis.urdf.xacro > teo_humanoid.urdf

	If you want to generate a SDF file from the generated URDF: (Requires gazebo)
	$ gzsdf print teo_humanoid.urdf > teo_humanoid.sdf
-->
<robot name="teo" xmlns:xacro="http://ros.org/wiki/xacro">
  <!-- TEO structure -->
  <!-- Include useful constants -->
  <!-- **** Torso **** -->
  <!-- base_link is rigidly attached to the robot root body.
  It is recommended to choose the robot waist as its root body -->
  <link name="base_link"/>
  <!--***************
    **** JOINTS ****
    ***************-->
  <!-- **** Fictitious joints **** -->
  <joint name="base_joint" type="fixed">
    <child link="waist"/>
    <parent link="base_link"/>
    <origin rpy="0 0 0" xyz="0 0 0"/>
  </joint>
  <!-- Definitions of parts of the robot body -->
  <!-- *** TEO TORSO PARAMETERS -->
  <!-- Link lengths -->
  <!--xacro:property name="waist_link2" value="0.287" /-->
  <!--xacro:property name="torso_link2" value="0.06" /-->
  <!-- Minimum angles -->
  <!-- Maximum angles -->
  <!-- Effort limit of the angles -->
  <!-- Velocity limit of the angles-->
  <!-- Damping of the joints-->
  <!-- Friction of the joints-->
  <!-- IT'S NOT USED IN GAZEBO-->
  <!-- Joint reductions-->
  <!-- *** TORSO TREE -->
  <!-- Links -->
  <link name="waist">
    <inertial>
      <origin rpy="0 0 0" xyz="-0.011195 0.000002 0.004350"/>
      <mass value="25.7044"/>
      <inertia ixx="1.500634e-5" ixy="-0.000041e-5" ixz="-0.000532e-5" iyy="0.703110e-5" iyz="0.000" izz="2.058404e-5"/>
    </inertial>
    <visual>
      <origin rpy="0 0 0" xyz="0 0 0"/>
      <geometry>
        <mesh filename="package://teo_description/meshes/torso/waist-base.stl"/>
      </geometry>
      <material name="teoBlack"/>
    </visual>
    <visual>
      <origin rpy="0 0 0" xyz="0 0 0.07336"/>
      <geometry>
        <mesh filename="package://teo_description/meshes/torso/waist-link.stl"/>
      </geometry>
      <material name="teoGray"/>
    </visual>
  </link>
  <link name="waist_yaw_link">
    <inertial>
      <origin rpy="0 0 0" xyz="-0.004091 -0.001037 -0.024630"/>
      <mass value="0.1"/>
      <inertia ixx="0.028026e-5" ixy="-0.000029e-5" ixz="-0.000422e-5" iyy="0.012750e-5" iyz="0.000044e-5" izz="0.020857e-5"/>
    </inertial>
    <visual>
      <origin rpy="0 0 0" xyz="0 0 -0.001"/>
      <geometry>
        <mesh filename="package://teo_description/meshes/torso/waist-yaw.stl"/>
      </geometry>
      <material name="teoGray"/>
    </visual>
    <!-- <collision>
      <origin rpy="0 0 0" xyz="0 0 0.025"/>
      <geometry>
        <sphere radius="1.0"/> THIS LINE WAS COMMENTED OUT
        <cylinder length="0.06" radius="0.02"/>
      </geometry>
    </collision> -->
  </link>
  <link name="waist_pitch_link">
     <!-- CUIDADO ESTE LINK PUEDE DAR PROBLEMEMAS PUEDE QUE EL STL ESTE MAL-->
    <inertial> 
      <origin rpy="0 0 0" xyz="0.028949 -0.000006 0.146571"/>
      <mass value="1.0"/>
      <inertia ixx="38.534004e-5" ixy="-0.000441e-5" ixz="-2.351565e-5" iyy="17.888283e-5" iyz="-0.026233e-5" izz="29.913538e-5"/>
    </inertial>
    <visual>
      <origin rpy="0 0 0" xyz="0 0 0"/>
      <geometry>
        <mesh filename="package://teo_description/meshes/torso/waist-pitch.stl"/>
      </geometry>
      <material name="teoGray"/>
    </visual>
    <collision>
      <origin rpy="1.57079632679 0 0" xyz="0 0 0"/>
      <geometry>
        <!--sphere radius="1.0"/-->
        <cylinder length="0.06" radius="0.02"/>
      </geometry>
    </collision>
    <visual>
      <origin rpy="0 0 0" xyz="0 0 0.06"/>
      <geometry>
        <mesh filename="package://teo_description/meshes/torso/torso.stl"/>
      </geometry>
      <material name="teoGray"/>
    </visual>
    <visual>
      <origin rpy="0 0 0" xyz="0 0.25486 0.305"/>
      <geometry>
        <mesh filename="package://teo_description/meshes/torso/L-torso-shoulder.stl"/>
      </geometry>
      <material name="teoGray"/>
    </visual>
    <visual>
      <origin rpy="0 0 0" xyz="0 -0.25486 0.305"/>
      <geometry>
        <mesh filename="package://teo_description/meshes/torso/R-torso-shoulder.stl"/>
      </geometry>
      <material name="LightGrey"/>
    </visual>
    <visual>
      <origin rpy="0 0 0" xyz="0 0 0.346"/>
      <geometry>
        <mesh filename="package://teo_description/meshes/torso/neck.stl"/>
      </geometry>
      <material name="LightGrey"/>
    </visual>
    <visual>
      <origin rpy="0 0 0" xyz="0 0 0.434"/>
      <geometry>
        <mesh filename="package://teo_description/meshes/torso/head.stl"/>
      </geometry>
      <material name="LightGrey"/>
    </visual>
    <collision>
      <origin rpy="0 0 0" xyz="0 0 0.1"/>
      <geometry>
        <box size="0.18 0.42 0.292"/>
      </geometry>
    </collision>
  </link>
  <!-- Joints -->
  <joint name="waist_yaw" type="revolute">
    <parent link="waist"/>
    <child link="waist_yaw_link"/>
    <origin rpy="0 0 0" xyz="0.0 0 0.1907"/>
    <axis xyz="0 0 1"/>
    <limit effort="30.0" lower="-0.785398163397" upper="0.523598775598" velocity="3.0"/>
  </joint>
  <joint name="waist_pitch" type="revolute">
    <parent link="waist_yaw_link"/>
    <child link="waist_pitch_link"/>
    <origin rpy="0 0 0" xyz="-0.0 0 0"/>
    <axis xyz="0 1 0"/>
    <limit effort="30.0" lower="-0.785398163397" upper="0.523598775598" velocity="3.0"/>
  </joint>
  <transmission name="waist_yaw_trans">
    <type>transmission_interface/SimpleTransmission</type>
    <joint name="waist_yaw">
      <hardwareInterface>EffortJointInterface</hardwareInterface>
    </joint>
    <actuator name="waist_yaw_motor">
      <mechanicalReduction>1.0</mechanicalReduction>
    </actuator>
  </transmission>
  <transmission name="waist_pitch_trans">
    <type>transmission_interface/SimpleTransmission</type>
    <joint name="waist_pitch">
      <hardwareInterface>EffortJointInterface</hardwareInterface>
    </joint>
    <actuator name="waist_pitch_motor">
      <mechanicalReduction>1.0</mechanicalReduction>
    </actuator>
  </transmission>
  <!-- *** TEO LEG PARAMETERS -->
  <!-- Link lengths -->
  <!-- Hip -->
  <!-- Hip -->
  <!-- Femur -->
  <!-- Tibia -->
  <!-- Patella -->
  <!-- Astragalus -->
  <!-- Minimum angles -->
  <!-- Maximum angles -->
  <!-- Effort limit of the angles -->
  <!-- Velocity limit of the angles-->
  <!-- Damping of the joints-->
  <!-- Friction of the joints-->
  <!-- IT'S NOT USED IN GAZEBO-->
  <!-- Joint reductions-->
  <!-- *** TEO LEG MACROS -->
  <!-- Links -->
  <!-- Joints -->
  <link name="l_hip_yaw_link">
    <inertial>
      <origin rpy="0 0 0" xyz="0.000949 0.000000 0.055583"/>
      <mass value="0.001"/>
      <inertia ixx="0.034076e-5" ixy="0.0" ixz="-0.000054e-5" iyy="0.057638e-5" iyz="0.0" izz="0.037186e-5"/>
    </inertial>
    <visual>
      <origin rpy="0 0 0" xyz="0 0 0"/>
      <geometry>
        <mesh filename="package://teo_description/meshes/legs/l_hip_yaw.stl"/>
      </geometry>
      <material name="teoGray"/>
    </visual>
    <!--<collision>
      <origin rpy="0 1.571 0" xyz="0 0 0.045"/>
      <geometry>
        <cylinder length="0.13" radius="0.045"/>
      </geometry>
    </collision> -->
  </link>
  <link name="l_hip_roll_link">
    <inertial>
      <origin rpy="0 0 0" xyz="0.006983 0.001958 0.000002"/>
      <mass value="0.001"/>
      <inertia ixx="0.036847e-5" ixy="0.000434e-5" ixz="0.000001e-5" iyy="0.019052e-5" iyz="0.0" izz="0.045536e-5"/>
    </inertial>
    <visual>
      <origin rpy="0 0 0" xyz="0 0 0"/>
      <geometry>
        <mesh filename="package://teo_description/meshes/legs/l_hip_pitch.stl"/>
      </geometry>
      <material name="teoGray"/>
    </visual>
  </link>
  <link name="l_femur_link">
    <inertial>
      <origin rpy="0 0 0" xyz="-0.013877 0.000000 -0.172570"/>
      <mass value="1.844"/>
      <inertia ixx="4.453649e-5" ixy="-0.000001e-5" ixz="0.130500e-5" iyy="4.463490e-5" iyz="0.000004e-5" izz="2.207084e-5"/>
    </inertial>
    <visual>
      <origin rpy="0 0 0" xyz="0 0 0"/>
      <geometry>
        <mesh filename="package://teo_description/meshes/legs/l_femur.stl"/>
      </geometry>
      <material name="teoGray"/>
    </visual>
    <collision>
      <geometry>
        <box size="0.1 0.1 0.33"/>
      </geometry>
      <origin rpy="0 0 0" xyz="0 0 -0.165"/>
    </collision>
  </link>
  <link name="l_tibia_link">
    <inertial>
      <origin rpy="0 0 0" xyz="-0.010351 -0.000000 -0.142720"/>
      <mass value="2.0817"/>
      <inertia ixx="4.644212e-5" ixy="0.0" ixz="-0.000732e-5" iyy="4.548272e-5" iyz="0.000001e-5" izz="0.816616e-5"/>
    </inertial>
    <visual>
      <origin rpy="0 0 0" xyz="0.0 0.0 0.0"/>
      <geometry>
        <mesh filename="package://teo_description/meshes/legs/l_tibia.stl"/>
      </geometry>
      <material name="teoGray"/>
    </visual>
    <collision>
      <geometry>
        <box size="0.05 0.033 0.05"/>
      </geometry>
      <origin rpy="0 0 0" xyz="0 -0.033 -0.275"/>
    </collision>
  </link>
  <link name="l_ankle_pitch_link">
    <inertial>
      <origin rpy="0 0 0" xyz="-0.007123 -0.002571 -0.000000"/>
      <mass value="1.0"/>
      <inertia ixx="0.010237e-5" ixy="0.000014e-5" ixz="0.0" iyy="0.035107e-5" iyz="-0.0" izz="0.035006e-5"/>
    </inertial>
    <visual>
      <origin rpy="0 0 0" xyz="0 0 0"/>
      <geometry>
        <mesh filename="package://teo_description/meshes/legs/l_ankle_pitch.stl"/>
      </geometry>
      <material name="teoGray"/>
    </visual>
  </link>
  <link name="l_astragalus_link"> 
	<!-- CUIDADO EL STL PUEDE ESTAR MAL -->
    <inertial>
      <origin rpy="0 0 0" xyz="-0.002598 -0.000020 -0.028278"/>
      <mass value="3.8994"/>
      <inertia ixx="0.041541e-5" ixy="0.0" ixz="-0.001468e-5" iyy="0.076860e-5" iyz="0.0" izz="0.066049e-5"/>
    </inertial>
    <visual>
      <origin rpy="0 0 0" xyz="0 0 0"/>
      <geometry>
        <mesh filename="package://teo_description/meshes/legs/l_ankle_roll.stl"/>
      </geometry>
      <material name="teoGray"/>
    </visual>
    <visual>
      <origin rpy="0 0 0" xyz="0 0 -0.073"/>
      <geometry>
        <mesh filename="package://teo_description/meshes/legs/l_ankle_sensorFT.stl"/>
      </geometry>
    </visual>
  </link>
  <link name="l_sole">
    <inertial>
      <origin rpy="0 0 0" xyz="0.018018 -0.002836 0.011245"/>
      <mass value="0.001"/>
      <inertia ixx="0.065992e-5" ixy="0.010716e-5" ixz="0.008960e-5" iyy="0.167825e-5" iyz="-0.000847e-5" izz="0.225319e-5"/>
    </inertial>
    <visual>
      <origin rpy="0 0 0" xyz="0 0 0"/>
      <geometry>
        <mesh filename="package://teo_description/meshes/legs/l_foot.stl"/>
      </geometry>
      <material name="teoGray"/>
    </visual>
    <collision>
      <geometry>
        <box size="0.08 0.08 0.124"/>
      </geometry>
      <origin rpy="0 0 0" xyz="0 0 -0.062"/>
    </collision>
    <visual>
      <origin rpy="0 0 0" xyz="0 0 0"/>
      <geometry>
        <mesh filename="package://teo_description/meshes/legs/l_union_sensorFT_foot.stl"/>
      </geometry>
      <material name="teoBlue"/>
    </visual>
  </link>
  <link name="r_hip_yaw_link">
    <inertial>
      <origin rpy="0 0 0" xyz="0.000949 0.000000 0.055583"/>
      <mass value="0.001"/>
      <inertia ixx="0.034076e-5" ixy="0.0" ixz="-0.000054e-5" iyy="0.057638e-5" iyz="0.0" izz="0.037186e-5"/>
    </inertial>
    <visual>
      <origin rpy="0 0 0" xyz="0 0 0"/>
      <geometry>
        <mesh filename="package://teo_description/meshes/legs/r_hip_yaw.stl"/>
      </geometry>
      <material name="teoGray"/>
    </visual>
    <!--<collision>
      <origin rpy="0 1.571 0" xyz="0 0 0.045"/>
      <geometry>
        <cylinder length="0.13" radius="0.045"/>
      </geometry>
    </collision>-->
  </link>
  <link name="r_hip_roll_link">
    <inertial>
      <origin rpy="0 0 0" xyz="0.006983 0.001958 0.000002"/>
      <mass value="0.001"/>
      <inertia ixx="0.036847e-5" ixy="0.000434e-5" ixz="0.000001e-5" iyy="0.019052e-5" iyz="0.0" izz="0.045536e-5"/>
    </inertial>
    <visual>
      <origin rpy="0 0 0" xyz="0 0 0"/>
      <geometry>
        <mesh filename="package://teo_description/meshes/legs/r_hip_pitch.stl"/>
      </geometry>
      <material name="teoGray"/>
    </visual>
  </link>
  <link name="r_femur_link">
    <inertial>
      <origin rpy="0 0 0" xyz="-0.013877 0.000000 -0.172570"/>
      <mass value="1.844"/>
      <inertia ixx="4.453648e-5" ixy="-0.000001e-5" ixz="0.130498e-5" iyy="4.463490e-5" iyz="0.000003e-5" izz="2.207083e-5"/>
    </inertial>
    <visual>
      <origin rpy="0 0 0" xyz="0 0 0"/>
      <geometry>
        <mesh filename="package://teo_description/meshes/legs/r_femur.stl"/>
      </geometry>
      <material name="teoGray"/>
    </visual>
    <collision>
      <geometry>
        <box size="0.1 0.1 0.33"/>
      </geometry>
      <origin rpy="0 0 0" xyz="0 0 -0.165"/>
    </collision>
  </link>
  <link name="r_tibia_link">
    <inertial>
      <origin rpy="0 0 0" xyz="-0.010351 0.000000 -0.142721"/>
      <mass value="2.0817"/>
      <inertia ixx="4.644211e-5" ixy="0.0" ixz="-0.000732e-5" iyy="4.548272e-5" iyz="-0.000002e-5" izz="0.816616e-5"/>
    </inertial>
    <visual>
      <origin rpy="0 0 0" xyz="0.0 0.0 0.0"/>
      <geometry>
        <mesh filename="package://teo_description/meshes/legs/r_tibia.stl"/>
      </geometry>
      <material name="teoGray"/>
    </visual>
    <collision>
      <geometry>
        <box size="0.05 0.033 0.05"/>
      </geometry>
      <origin rpy="0 0 0" xyz="0 0.033 -0.275"/>
    </collision>
  </link>
  <link name="r_ankle_pitch_link">
    <inertial>
      <origin rpy="0 0 0" xyz="-0.007339 -0.012149 0.000003"/>
      <mass value="1.0"/>
      <inertia ixx="0.033782e-5" ixy="-0.000165e-5" ixz="0.0" iyy="0.038475e-5" iyz="-0.0" izz="0.058551e-5"/>
    </inertial>
    <visual>
      <origin rpy="0 0 0" xyz="0 0 0"/>
      <geometry>
        <mesh filename="package://teo_description/meshes/legs/r_ankle_pitch.stl"/>
      </geometry>
      <material name="teoGray"/>
    </visual>
  </link>
  <link name="r_astragalus_link">
    <inertial>
      <origin rpy="0 0 0" xyz="-0.001109 -0.000108 -0.028278"/>
      <mass value="3.8994"/>
      <inertia ixx="0.041548e-5" ixy="0.000185e-5" ixz="-0.001761e-5" iyy="0.077750e-5" iyz="0.000059e-5" izz="0.066946e-5"/>
    </inertial>
    <visual>
      <origin rpy="0 0 0" xyz="0 0 0"/>
      <geometry>
        <mesh filename="package://teo_description/meshes/legs/r_ankle_roll.stl"/>
      </geometry>
      <material name="teoGray"/>
    </visual>
    <visual>
      <origin rpy="0 0 0" xyz="0 0 -0.073"/>
      <geometry>
        <mesh filename="package://teo_description/meshes/legs/r_ankle_sensorFT.stl"/>
      </geometry>
    </visual>
  </link>
  <link name="r_sole">
    <inertial>
      <origin rpy="0 0 0" xyz="0.022629 0.002448 0.011325"/>
      <mass value="0.001"/>
      <inertia ixx="0.066990e-5" ixy="-0.009295e-5" ixz="0.009066e-5" iyy="0.169929e-5" iyz="0.000708e-5" izz="0.228359e-5"/>
    </inertial>
    <visual>
      <origin rpy="0 0 0" xyz="0 0 0"/>
      <geometry>
        <mesh filename="package://teo_description/meshes/legs/r_foot.stl"/>
      </geometry>
      <material name="teoGray"/>
    </visual>
    <collision>
      <geometry>
        <box size="0.08 0.08 0.124"/>
      </geometry>
      <origin rpy="0 0 0" xyz="0 0 -0.062"/>
    </collision>
    <visual>
      <origin rpy="0 0 0" xyz="0 0 0"/>
      <geometry>
        <mesh filename="package://teo_description/meshes/legs/r_union_sensorFT_foot.stl"/>
      </geometry>
      <material name="teoBlue"/>
    </visual>
  </link>
  <joint name="l_hip_yaw" type="revolute">
    <parent link="waist"/>
    <child link="l_hip_yaw_link"/>
    <origin rpy="0 0 0" xyz="0 0.146 -0.10237"/>
    <!--y=Leg_link1-->
    <axis xyz="0 0 1"/>
    <limit effort="30.0" lower="-0.523598775598" upper="0.418879020479" velocity="3.0"/>
    <dynamics damping="0.0" friction="0.0"/>
  </joint>
  <joint name="l_hip_roll" type="revolute">
    <parent link="l_hip_yaw_link"/>
    <child link="l_hip_roll_link"/>
    <origin rpy="0 0 0" xyz="0 0 0"/>
    <axis xyz="1 0 0"/>
    <limit effort="30.0" lower="-0.698131700798" upper="0.523598775598" velocity="3.0"/>
    <dynamics damping="0.0" friction="0.0"/>
  </joint>
  <joint name="l_hip_pitch" type="revolute">
    <parent link="l_hip_roll_link"/>
    <child link="l_femur_link"/>
    <origin rpy="0 0 0" xyz="0 0 0"/>
    <axis xyz="0 1 0"/>
    <limit effort="30.0" lower="-2.09439510239" upper="0.785398163397" velocity="3.0"/>
    <dynamics damping="0.0" friction="0.0"/>
  </joint>
  <joint name="l_knee_pitch" type="revolute">
    <parent link="l_femur_link"/>
    <child link="l_tibia_link"/>
    <origin rpy="0 0 0" xyz="0 0 -0.33"/>
    <axis xyz="0 1 0"/>
    <limit effort="30.0" lower="0.0" upper="1.57079632679" velocity="3.0"/>
    <dynamics damping="0.0" friction="0.0"/>
  </joint>
  <joint name="l_ankle_pitch" type="revolute">
    <parent link="l_tibia_link"/>
    <child link="l_ankle_pitch_link"/>
    <origin rpy="0 0 0" xyz="0 -0.033 -0.3"/>
    <axis xyz="0 1 0"/>
    <limit effort="30.0" lower="-0.349065850399" upper="0.349065850399" velocity="3.0"/>
    <dynamics damping="0.0" friction="0.0"/>
  </joint>
  <joint name="l_ankle_roll" type="revolute">
    <parent link="l_ankle_pitch_link"/>
    <child link="l_astragalus_link"/>
    <origin rpy="0 0 0" xyz="0 0 0"/>
    <axis xyz="1 0 0"/>
    <limit effort="30.0" lower="-1.4835298642" upper="1.4835298642" velocity="3.0"/>
    <dynamics damping="0.0" friction="0.0"/>
  </joint>
  <joint name="l_sole_joint" type="fixed">
    <parent link="l_astragalus_link"/>
    <child link="l_sole"/>
    <origin rpy="0 0 0" xyz="0 0 -0.124"/>
  </joint>
  <transmission name="l_hip_yaw_trans">
    <type>transmission_interface/SimpleTransmission</type>
    <joint name="l_hip_yaw">
      <hardwareInterface>PositionJointInterface</hardwareInterface>
    </joint>
    <actuator name="l_hip_yaw_motor">
      <hardwareInterface>PositionJointInterface</hardwareInterface>
      <mechanicalReduction>1.0</mechanicalReduction>
    </actuator>
  </transmission>
  <transmission name="l_hip_roll_trans">
    <type>transmission_interface/SimpleTransmission</type>
    <joint name="l_hip_roll">
      <hardwareInterface>PositionJointInterface</hardwareInterface>
    </joint>
    <actuator name="l_hip_roll_motor">
      <hardwareInterface>PositionJointInterface</hardwareInterface>
      <mechanicalReduction>1.0</mechanicalReduction>
    </actuator>
  </transmission>
  <transmission name="l_hip_pitch_trans">
    <type>transmission_interface/SimpleTransmission</type>
    <joint name="l_hip_pitch">
      <hardwareInterface>PositionJointInterface</hardwareInterface>
    </joint>
    <actuator name="l_hip_pitch_motor">
      <hardwareInterface>PositionJointInterface</hardwareInterface>
      <mechanicalReduction>1.0</mechanicalReduction>
    </actuator>
  </transmission>
  <transmission name="l_knee_pitch_trans">
    <type>transmission_interface/SimpleTransmission</type>
    <joint name="l_knee_pitch">
      <hardwareInterface>PositionJointInterface</hardwareInterface>
    </joint>
    <actuator name="l_knee_pitch_motor">
      <hardwareInterface>PositionJointInterface</hardwareInterface>
      <mechanicalReduction>1.0</mechanicalReduction>
    </actuator>
  </transmission>
  <transmission name="l_ankle_pitch_trans">
    <type>transmission_interface/SimpleTransmission</type>
    <joint name="l_ankle_pitch">
      <hardwareInterface>PositionJointInterface</hardwareInterface>
    </joint>
    <actuator name="l_ankle_pitch_motor">
      <hardwareInterface>PositionJointInterface</hardwareInterface>
      <mechanicalReduction>1.0</mechanicalReduction>
    </actuator>
  </transmission>
  <transmission name="l_ankle_roll_trans">
    <type>transmission_interface/SimpleTransmission</type>
    <joint name="l_ankle_roll">
      <hardwareInterface>PositionJointInterface</hardwareInterface>
    </joint>
    <actuator name="l_ankle_roll_motor">
      <hardwareInterface>PositionJointInterface</hardwareInterface>
      <mechanicalReduction>1.0</mechanicalReduction>
    </actuator>
  </transmission>
  <joint name="r_hip_yaw" type="revolute">
    <parent link="waist"/>
    <child link="r_hip_yaw_link"/>
    <origin rpy="0 0 0" xyz="0 -0.146 -0.10237"/>
    <!--y=Leg_link1-->
    <axis xyz="0 0 1"/>
    <limit effort="30.0" lower="-0.523598775598" upper="0.418879020479" velocity="3.0"/>
    <dynamics damping="0.0" friction="0.0"/>
  </joint>
  <joint name="r_hip_roll" type="revolute">
    <parent link="r_hip_yaw_link"/>
    <child link="r_hip_roll_link"/>
    <origin rpy="0 0 0" xyz="0 0 0"/>
    <axis xyz="1 0 0"/>
    <limit effort="30.0" lower="-0.698131700798" upper="0.523598775598" velocity="3.0"/>
    <dynamics damping="0.0" friction="0.0"/>
  </joint>
  <joint name="r_hip_pitch" type="revolute">
    <parent link="r_hip_roll_link"/>
    <child link="r_femur_link"/>
    <origin rpy="0 0 0" xyz="0 0 0"/>
    <axis xyz="0 1 0"/>
    <limit effort="30.0" lower="-2.09439510239" upper="0.785398163397" velocity="3.0"/>
    <dynamics damping="0.0" friction="0.0"/>
  </joint>
  <joint name="r_knee_pitch" type="revolute">
    <parent link="r_femur_link"/>
    <child link="r_tibia_link"/>
    <origin rpy="0 0 0" xyz="0 0 -0.33"/>
    <axis xyz="0 1 0"/>
    <limit effort="30.0" lower="0.0" upper="1.57079632679" velocity="3.0"/>
    <dynamics damping="0.0" friction="0.0"/>
  </joint>
  <joint name="r_ankle_pitch" type="revolute">
    <parent link="r_tibia_link"/>
    <child link="r_ankle_pitch_link"/>
    <origin rpy="0 0 0" xyz="0 0.033 -0.3"/>
    <axis xyz="0 1 0"/>
    <limit effort="30.0" lower="-0.349065850399" upper="0.349065850399" velocity="3.0"/>
    <dynamics damping="0.0" friction="0.0"/>
  </joint>
  <joint name="r_ankle_roll" type="revolute">
    <parent link="r_ankle_pitch_link"/>
    <child link="r_astragalus_link"/>
    <origin rpy="0 0 0" xyz="0 0 0"/>
    <axis xyz="1 0 0"/>
    <limit effort="30.0" lower="-1.4835298642" upper="1.4835298642" velocity="3.0"/>
    <dynamics damping="0.0" friction="0.0"/>
  </joint>
  <joint name="r_sole_joint" type="fixed">
    <parent link="r_astragalus_link"/>
    <child link="r_sole"/>
    <origin rpy="0 0 0" xyz="0 0 -0.124"/>
  </joint>
  <transmission name="r_hip_yaw_trans">
    <type>transmission_interface/SimpleTransmission</type>
    <joint name="r_hip_yaw">
      <hardwareInterface>PositionJointInterface</hardwareInterface>
    </joint>
    <actuator name="r_hip_yaw_motor">
      <hardwareInterface>PositionJointInterface</hardwareInterface>
      <mechanicalReduction>1.0</mechanicalReduction>
    </actuator>
  </transmission>
  <transmission name="r_hip_roll_trans">
    <type>transmission_interface/SimpleTransmission</type>
    <joint name="r_hip_roll">
      <hardwareInterface>PositionJointInterface</hardwareInterface>
    </joint>
    <actuator name="r_hip_roll_motor">
      <hardwareInterface>PositionJointInterface</hardwareInterface>
      <mechanicalReduction>1.0</mechanicalReduction>
    </actuator>
  </transmission>
  <transmission name="r_hip_pitch_trans">
    <type>transmission_interface/SimpleTransmission</type>
    <joint name="r_hip_pitch">
      <hardwareInterface>PositionJointInterface</hardwareInterface>
    </joint>
    <actuator name="r_hip_pitch_motor">
      <hardwareInterface>PositionJointInterface</hardwareInterface>
      <mechanicalReduction>1.0</mechanicalReduction>
    </actuator>
  </transmission>
  <transmission name="r_knee_pitch_trans">
    <type>transmission_interface/SimpleTransmission</type>
    <joint name="r_knee_pitch">
      <hardwareInterface>PositionJointInterface</hardwareInterface>
    </joint>
    <actuator name="r_knee_pitch_motor">
      <hardwareInterface>PositionJointInterface</hardwareInterface>
      <mechanicalReduction>1.0</mechanicalReduction>
    </actuator>
  </transmission>
  <transmission name="r_ankle_pitch_trans">
    <type>transmission_interface/SimpleTransmission</type>
    <joint name="r_ankle_pitch">
      <hardwareInterface>PositionJointInterface</hardwareInterface>
    </joint>
    <actuator name="r_ankle_pitch_motor">
      <hardwareInterface>PositionJointInterface</hardwareInterface>
      <mechanicalReduction>1.0</mechanicalReduction>
    </actuator>
  </transmission>
  <transmission name="r_ankle_roll_trans">
    <type>transmission_interface/SimpleTransmission</type>
    <joint name="r_ankle_roll">
      <hardwareInterface>PositionJointInterface</hardwareInterface>
    </joint>
    <actuator name="r_ankle_roll_motor">
      <hardwareInterface>PositionJointInterface</hardwareInterface>
      <mechanicalReduction>1.0</mechanicalReduction>
    </actuator>
  </transmission>
  <!-- *** TEO ARM PARAMETERS -->
  <!-- Link lengths (meters)-->
  <!--xacro:property name="chest_link1" value="0.0" />
	<xacro:property name="chest_link2" value="0.245" /-->
  <!-- Clavicle -->
  <!-- Humerus -->
  <!-- Ulna -->
  <!-- Minimum angles (degrees) -->
  <!-- Maximum angles (degrees) -->
  <!-- Effort limit of the angles -->
  <!-- Velocity limit of the angles-->
  <!-- Damping of the joints-->
  <!-- Friction of the joints-->
  <!-- IT'S NOT USED IN GAZEBO-->
  <!-- Joint reductions-->
  <!-- *** TEO ARM MACROS -->
  <!-- Links -->
  <!-- Joints -->
  <link name="l_shoulder_pitch_link">
    <inertial>
      <origin rpy="0 0 0" xyz="-0.002787 -0.020318 0.011855"/>
      <mass value="0.005"/>
      <inertia ixx="0.059121e-5" ixy="0.000603e-5" ixz="0.000103e-5" iyy="0.024956e-5" iyz="0.005131e-5" izz="0.050653e-5"/>
    </inertial>
    <visual>
      <origin rpy="0 0 0" xyz="0 0 0"/>
      <geometry>
        <mesh filename="package://teo_description/meshes/arms/l_shoulder_pitch.stl"/>
      </geometry>
      <material name="teoGray"/>
    </visual>
    <!--<collision>
      <geometry>
        <box size="0.1 0.34 0.1"/>
      </geometry>
      <origin rpy="0 0 0" xyz="0 0 0"/>
    </collision>-->
  </link>
  <link name="l_shoulder_roll_link">
    <inertial>
      <origin rpy="0 0 0" xyz="-0.006929 0.010211 -0.034506"/>
      <mass value="0.005"/>
      <inertia ixx="0.018036e-5" ixy="-0.000773e-5" ixz="0.002406e-5" iyy="0.024499e-5" iyz="0.001826e-5" izz="0.013143e-5"/>
    </inertial>
    <visual>
      <origin rpy="0 0 0" xyz="0 0 0"/>
      <geometry>
        <mesh filename="package://teo_description/meshes/arms/l_shoulder_roll.stl"/>
      </geometry>
      <material name="teoGray"/>
    </visual>
    <!--<collision>
      <geometry>
        <box size="0.1 0.34 0.1"/>
      </geometry>
      <origin rpy="0 0 0" xyz="0 0 0"/>
    </collision>-->
  </link>
  <link name="l_shoulder_yaw_link">
    <inertial>
      <origin rpy="0 0 0" xyz="0.003730 -0.000080 0.062982"/>
      <mass value="1.750625"/>
      <inertia ixx="0.227681e-5" ixy="0.0" ixz="0.0" iyy="0.224821e-5" iyz="-0.000684e-5" izz="0.032283e-5"/>
    </inertial>
    <visual>
      <origin rpy="0 0 0" xyz="0 0 -0.12126"/>
      <geometry>
        <mesh filename="package://teo_description/meshes/arms/l_shoulder_yaw.stl"/>
      </geometry>
      <material name="teoGray"/>
    </visual>
    <visual>
      <origin rpy="0 0 0" xyz="0 0 -0.27651"/>
      <geometry>
        <mesh filename="package://teo_description/meshes/arms/l_humerus.stl"/>
      </geometry>
      <material name="teoGray"/>
    </visual>
    <visual>
      <origin rpy="0 0 0" xyz="0 0 -0.28351"/>
      <geometry>
        <mesh filename="package://teo_description/meshes/arms/l_union_humerus_elbow.stl"/>
      </geometry>
      <material name="teoGray"/>
    </visual>
    <collision>
      <geometry>
        <box size="0.08 0.08 0.32901"/>
      </geometry>
      <origin rpy="0 0 0" xyz="0 0 -0.164505"/>
    </collision>
  </link>
  <link name="l_elbow_pitch_link">
    <inertial>
      <origin rpy="0 0 0" xyz="0.000000 0.001000 -0.000588"/>
      <mass value="2.396"/>
      <inertia ixx="0.059390e-5" ixy="0.0" ixz="0.0" iyy="0.060871e-5" iyz="0.0" izz="0.023257e-5"/>
    </inertial>
    <visual>
      <origin rpy="0 0 0" xyz="0 0 0"/>
      <geometry>
        <mesh filename="package://teo_description/meshes/arms/l_elbow_pitch.stl"/>
      </geometry>
      <material name="teoGray"/>
    </visual>
    <visual>
      <origin rpy="0 0 0" xyz="0 0 -0.11324"/>
      <geometry>
        <mesh filename="package://teo_description/meshes/arms/l_elbow_link.stl"/>
      </geometry>
    </visual>
    <visual>
      <origin rpy="0 0 0" xyz="0 0 -0.11324"/>
      <geometry>
        <mesh filename="package://teo_description/meshes/arms/l_union_elbow_wrist.stl"/>
      </geometry>
      <material name="teoGray"/>
    </visual>
    <collision>
      <geometry>
        <box size="0.06 0.06 0.202"/>
      </geometry>
      <origin rpy="0 0 0" xyz="0 0 -0.101"/>
    </collision>
  </link>
  <link name="l_wrist_yaw_link">
    <inertial>
      <origin rpy="0 0 0" xyz="-0.004657 0.000684 0.035884"/>
      <mass value="0.005"/>
      <inertia ixx="0.004543e-5" ixy="0.000068e-5" ixz="0.000070e-5" iyy="0.003969e-5" iyz="-0.000074e-5" izz="0.002118e-5"/>
    </inertial>
    <visual>
      <origin rpy="0 0 0" xyz="0 0 0"/>
      <geometry>
        <mesh filename="package://teo_description/meshes/arms/l_wrist_yaw.stl"/>
      </geometry>
      <material name="teoGray"/>
    </visual>
    <!--<collision>
      <geometry>
        <box size="0.03 0.03 0.03"/>
      </geometry>
      <origin rpy="0 0 0" xyz="0 0 -0.015"/>
    </collision>-->
  </link>
  <link name="l_wrist_pitch_link">
    <inertial>
      <origin rpy="0 0 0" xyz="-0.002438 0.004651 -0.044838"/>
      <mass value="0.3"/>
      <inertia ixx="-0.008340e-5" ixy="0.003467e-5" ixz="-0.005569e-5" iyy="-0.013678e-5" iyz="0.003820e-5" izz="0.005135e-5"/>
    </inertial>
    <visual>
      <origin rpy="0 0 0" xyz="0 0 0"/>
      <geometry>
        <mesh filename="package://teo_description/meshes/arms/l_wrist_pitch.stl"/>
      </geometry>
      <material name="teoGray"/>
    </visual>
    <visual>
      <origin rpy="0 0 0" xyz="0 0 -0.056"/>
      <geometry>
        <mesh filename="package://teo_description/meshes/arms/l_wrist_sensorFT.stl"/>
      </geometry>
      <material name="teoGray"/>
    </visual>
    <visual>
      <origin rpy="0 0 0" xyz="0 0 -0.056"/>
      <geometry>
        <mesh filename="package://teo_description/meshes/arms/l_hand.stl"/>
      </geometry>
      <material name="teoGray"/>
    </visual>
    <collision>
      <geometry>
        <box size="0.03 0.03 0.03"/>
      </geometry>
      <origin rpy="0 0 0" xyz="0 0 -0.015"/>
    </collision>
  </link>
  <link name="r_shoulder_pitch_link">
    <inertial>
      <origin rpy="0 0 0" xyz="-0.002758 0.020318 0.011855"/>
      <mass value="0.005"/>
      <inertia ixx="0.059121e-5" ixy="-0.000580e-5" ixz="0.000116e-5" iyy="0.024956e-5" iyz="-0.005131e-5" izz="0.050652e-5"/>
    </inertial>
    <visual>
      <origin rpy="0 0 0" xyz="0 0 0"/>
      <geometry>
        <mesh filename="package://teo_description/meshes/arms/r_shoulder_pitch.stl"/>
      </geometry>
      <material name="teoGray"/>
    </visual>
    <!--<collision>
      <geometry>
        <box size="0.1 0.34 0.1"/>
      </geometry>
      <origin rpy="0 0 0" xyz="0 0 0"/>
    </collision>-->
  </link>
  <link name="r_shoulder_roll_link">
    <inertial>
      <origin rpy="0 0 0" xyz="-0.006929 -0.010231 -0.034506"/>
      <mass value="0.005"/>
      <inertia ixx="0.018036e-5" ixy="0.000773e-5" ixz="0.002406e-5" iyy="0.024499e-5" iyz="-0.001826e-5" izz="0.013143e-5"/>
    </inertial>
    <visual>
      <origin rpy="0 0 0" xyz="0 0 0"/>
      <geometry>
        <mesh filename="package://teo_description/meshes/arms/r_shoulder_roll.stl"/>
      </geometry>
      <material name="teoGray"/>
    </visual>
    <!--<collision>
      <geometry>
        <box size="0.1 0.34 0.1"/>
      </geometry>
      <origin rpy="0 0 0" xyz="0 0 0"/>
    </collision>-->
  </link>
  <link name="r_shoulder_yaw_link">
    <inertial>
      <origin rpy="0 0 0" xyz="0.003730 0.000060 0.062982"/>
      <mass value="1.750625"/>
      <inertia ixx="0.227681e-5" ixy="0.0" ixz="0.0" iyy="0.224822e-5" iyz="0.000684e-5" izz="0.032283e-5"/>
    </inertial>
    <visual>
      <origin rpy="0 0 0" xyz="0 0 -0.12126"/>
      <geometry>
        <mesh filename="package://teo_description/meshes/arms/r_shoulder_yaw.stl"/>
      </geometry>
      <material name="teoGray"/>
    </visual>
    <visual>
      <origin rpy="0 0 0" xyz="0 0 -0.27651"/>
      <geometry>
        <mesh filename="package://teo_description/meshes/arms/r_humerus.stl"/>
      </geometry>
      <material name="teoGray"/>
    </visual>
    <visual>
      <origin rpy="0 0 0" xyz="0 0 -0.28351"/>
      <geometry>
        <mesh filename="package://teo_description/meshes/arms/r_union_humerus_elbow.stl"/>
      </geometry>
      <material name="teoGray"/>
    </visual>
    <collision>
      <geometry>
        <box size="0.08 0.08 0.32901"/>
      </geometry>
      <origin rpy="0 0 0" xyz="0 0 -0.164505"/>
    </collision>
  </link>
  <link name="r_elbow_pitch_link">
    <inertial>
      <origin rpy="0 0 0" xyz="0.000000 -0.001020 -0.000588"/>
      <mass value="2.396"/>
      <inertia ixx="0.059390e-5" ixy="0.0" ixz="0.0" iyy="0.060871e-5" iyz="0.0" izz="0.023257e-5"/>
    </inertial>
    <visual>
      <origin rpy="0 0 0" xyz="0 0 0"/>
      <geometry>
        <mesh filename="package://teo_description/meshes/arms/r_elbow_pitch.stl"/>
      </geometry>
      <material name="teoGray"/>
    </visual>
    <visual>
      <origin rpy="0 0 0" xyz="0 0 -0.11324"/>
      <geometry>
        <mesh filename="package://teo_description/meshes/arms/r_elbow_link.stl"/>
      </geometry>
    </visual>
    <visual>
      <origin rpy="0 0 0" xyz="0 0 -0.11324"/>
      <geometry>
        <mesh filename="package://teo_description/meshes/arms/r_union_elbow_wrist.stl"/>
      </geometry>
      <material name="teoGray"/>
    </visual>
    <collision>
      <geometry>
        <box size="0.06 0.06 0.202"/>
      </geometry>
      <origin rpy="0 0 0" xyz="0 0 -0.101"/>
    </collision>
  </link>
  <link name="r_wrist_yaw_link">
    <inertial>
      <origin rpy="0 0 0" xyz="-0.004657 -0.001356 0.035884"/>
      <mass value="0.005"/>
      <inertia ixx="0.004543e-5" ixy="0.000068e-5" ixz="0.000070e-5" iyy="0.003969e-5" iyz="-0.000074e-5" izz="0.002118e-5"/>
    </inertial>
    <visual>
      <origin rpy="0 0 0" xyz="0 0 0"/>
      <geometry>
        <mesh filename="package://teo_description/meshes/arms/r_wrist_yaw.stl"/>
      </geometry>
      <material name="teoGray"/>
    </visual>
    <!--<collision>
      <geometry>
        <box size="0.03 0.03 0.03"/>
      </geometry>
      <origin rpy="0 0 0" xyz="0 0 -0.015"/>
    </collision>-->
  </link>
  <link name="r_wrist_pitch_link">
    <inertial>
      <origin rpy="0 0 0" xyz="-0.002432 0.002560 -0.044838"/>
      <mass value="0.3"/>
      <inertia ixx="-0.008337e-5" ixy="0.003468e-5" ixz="-0.005567e-5" iyy="-0.013674e-5" iyz="0.005108e-5" izz="0.005142e-5"/>
    </inertial>
    <visual>
      <origin rpy="0 0 0" xyz="0 0 0"/>
      <geometry>
        <mesh filename="package://teo_description/meshes/arms/r_wrist_pitch.stl"/>
      </geometry>
      <material name="teoGray"/>
    </visual>
    <visual>
      <origin rpy="0 0 0" xyz="0 0 -0.056"/>
      <geometry>
        <mesh filename="package://teo_description/meshes/arms/r_wrist_sensorFT.stl"/>
      </geometry>
      <material name="teoGray"/>
    </visual>
    <visual>
      <origin rpy="0 0 0" xyz="0 0 -0.056"/>
      <geometry>
        <mesh filename="package://teo_description/meshes/arms/r_hand.stl"/>
      </geometry>
      <material name="teoGray"/>
    </visual>
    <collision>
      <geometry>
        <box size="0.03 0.03 0.03"/>
      </geometry>
      <origin rpy="0 0 0" xyz="0 0 -0.015"/>
    </collision>
  </link>
  <joint name="l_shoulder_pitch" type="revolute">
    <parent link="waist_pitch_link"/>
    <child link="l_shoulder_pitch_link"/>
    <origin rpy="0 0 0" xyz="-0.0 0.34 0.305"/>
    <axis xyz="0 1 0"/>
    <limit effort="30.0" lower="-3.14159265359" upper="3.14159265359" velocity="3.0"/>
  </joint>
  <joint name="l_shoulder_roll" type="revolute">
    <parent link="l_shoulder_pitch_link"/>
    <child link="l_shoulder_roll_link"/>
    <origin rpy="0 0 0" xyz="0 0 0"/>
    <axis xyz="1 0 0"/>
    <limit effort="30.0" lower="-0.785398163397" upper="2.09439510239" velocity="3.0"/>
  </joint>
  <joint name="l_shoulder_yaw" type="revolute">
    <parent link="l_shoulder_roll_link"/>
    <child link="l_shoulder_yaw_link"/>
    <origin rpy="0 0 0" xyz="0 0 0"/>
    <axis xyz="0 0 1"/>
    <limit effort="30.0" lower="-1.0471975512" upper="1.0471975512" velocity="3.0"/>
  </joint>
  <joint name="l_elbow_pitch" type="revolute">
    <parent link="l_shoulder_yaw_link"/>
    <child link="l_elbow_pitch_link"/>
    <origin rpy="0 0 0" xyz="0 0 -0.32901"/>
    <axis xyz="0 1 0"/>
    <limit effort="30.0" lower="-1.74532925199" upper="1.74532925199" velocity="3.0"/>
  </joint>
  <joint name="l_wrist_yaw" type="revolute">
    <parent link="l_elbow_pitch_link"/>
    <child link="l_wrist_yaw_link"/>
    <origin rpy="0 0 0" xyz="0 0 -0.202"/>
    <axis xyz="0 0 1"/>
    <limit effort="30.0" lower="-1.83259571459" upper="1.83259571459" velocity="3.0"/>
  </joint>
  <joint name="l_wrist_pitch" type="revolute">
    <parent link="l_wrist_yaw_link"/>
    <child link="l_wrist_pitch_link"/>
    <origin rpy="0 0 0" xyz="0 0 0"/>
    <axis xyz="0 1 0"/>
    <limit effort="30.0" lower="-0.698131700798" upper="0.959931088597" velocity="3.0"/>
  </joint>
  <transmission name="l_shoulder_pitch_trans">
    <type>transmission_interface/SimpleTransmission</type>
    <joint name="l_shoulder_pitch">
      <hardwareInterface>EffortJointInterface</hardwareInterface>
    </joint>
    <actuator name="l_shoulder_pitch_motor">
      <hardwareInterface>EffortJointInterface</hardwareInterface>
      <mechanicalReduction>1.0</mechanicalReduction>
    </actuator>
  </transmission>
  <transmission name="l_shoulder_roll_trans">
    <type>transmission_interface/SimpleTransmission</type>
    <joint name="l_shoulder_roll">
      <hardwareInterface>EffortJointInterface</hardwareInterface>
    </joint>
    <actuator name="l_shoulder_roll_motor">
      <hardwareInterface>EffortJointInterface</hardwareInterface>
      <mechanicalReduction>1.0</mechanicalReduction>
    </actuator>
  </transmission>
  <transmission name="l_shoulder_yaw_trans">
    <type>transmission_interface/SimpleTransmission</type>
    <joint name="l_shoulder_yaw">
      <hardwareInterface>EffortJointInterface</hardwareInterface>
    </joint>
    <actuator name="l_shoulder_yaw_motor">
      <hardwareInterface>EffortJointInterface</hardwareInterface>
      <mechanicalReduction>1.0</mechanicalReduction>
    </actuator>
  </transmission>
  <transmission name="l_elbow_pitch_trans">
    <type>transmission_interface/SimpleTransmission</type>
    <joint name="l_elbow_pitch">
      <hardwareInterface>EffortJointInterface</hardwareInterface>
    </joint>
    <actuator name="l_elbow_pitch_motor">
      <hardwareInterface>EffortJointInterface</hardwareInterface>
      <mechanicalReduction>1.0</mechanicalReduction>
    </actuator>
  </transmission>
  <transmission name="l_wrist_yaw_trans">
    <type>transmission_interface/SimpleTransmission</type>
    <joint name="l_wrist_yaw">
      <hardwareInterface>EffortJointInterface</hardwareInterface>
    </joint>
    <actuator name="l_wrist_yaw_motor">
      <hardwareInterface>EffortJointInterface</hardwareInterface>
      <mechanicalReduction>1.0</mechanicalReduction>
    </actuator>
  </transmission>
  <transmission name="l_wrist_pitch_trans">
    <type>transmission_interface/SimpleTransmission</type>
    <joint name="l_wrist_pitch">
      <hardwareInterface>EffortJointInterface</hardwareInterface>
    </joint>
    <actuator name="l_wrist_pitch_motor">
      <hardwareInterface>EffortJointInterface</hardwareInterface>
      <mechanicalReduction>1.0</mechanicalReduction>
    </actuator>
  </transmission>
  <joint name="r_shoulder_pitch" type="revolute">
    <parent link="waist_pitch_link"/>
    <child link="r_shoulder_pitch_link"/>
    <origin rpy="0 0 0" xyz="-0.0 -0.34 0.305"/>
    <axis xyz="0 1 0"/>
    <limit effort="30.0" lower="-3.14159265359" upper="3.14159265359" velocity="3.0"/>
  </joint>
  <joint name="r_shoulder_roll" type="revolute">
    <parent link="r_shoulder_pitch_link"/>
    <child link="r_shoulder_roll_link"/>
    <origin rpy="0 0 0" xyz="0 0 0"/>
    <axis xyz="1 0 0"/>
    <limit effort="30.0" lower="-0.785398163397" upper="2.09439510239" velocity="3.0"/>
  </joint>
  <joint name="r_shoulder_yaw" type="revolute">
    <parent link="r_shoulder_roll_link"/>
    <child link="r_shoulder_yaw_link"/>
    <origin rpy="0 0 0" xyz="0 0 0"/>
    <axis xyz="0 0 1"/>
    <limit effort="30.0" lower="-1.0471975512" upper="1.0471975512" velocity="3.0"/>
  </joint>
  <joint name="r_elbow_pitch" type="revolute">
    <parent link="r_shoulder_yaw_link"/>
    <child link="r_elbow_pitch_link"/>
    <origin rpy="0 0 0" xyz="0 0 -0.32901"/>
    <axis xyz="0 1 0"/>
    <limit effort="30.0" lower="-1.74532925199" upper="1.74532925199" velocity="3.0"/>
  </joint>
  <joint name="r_wrist_yaw" type="revolute">
    <parent link="r_elbow_pitch_link"/>
    <child link="r_wrist_yaw_link"/>
    <origin rpy="0 0 0" xyz="0 0 -0.202"/>
    <axis xyz="0 0 1"/>
    <limit effort="30.0" lower="-1.83259571459" upper="1.83259571459" velocity="3.0"/>
  </joint>
  <joint name="r_wrist_pitch" type="revolute">
    <parent link="r_wrist_yaw_link"/>
    <child link="r_wrist_pitch_link"/>
    <origin rpy="0 0 0" xyz="0 0 0"/>
    <axis xyz="0 1 0"/>
    <limit effort="30.0" lower="-0.698131700798" upper="0.959931088597" velocity="3.0"/>
  </joint>
  <transmission name="r_shoulder_pitch_trans">
    <type>transmission_interface/SimpleTransmission</type>
    <joint name="r_shoulder_pitch">
      <hardwareInterface>EffortJointInterface</hardwareInterface>
    </joint>
    <actuator name="r_shoulder_pitch_motor">
      <hardwareInterface>EffortJointInterface</hardwareInterface>
      <mechanicalReduction>1.0</mechanicalReduction>
    </actuator>
  </transmission>
  <transmission name="r_shoulder_roll_trans">
    <type>transmission_interface/SimpleTransmission</type>
    <joint name="r_shoulder_roll">
      <hardwareInterface>EffortJointInterface</hardwareInterface>
    </joint>
    <actuator name="r_shoulder_roll_motor">
      <hardwareInterface>EffortJointInterface</hardwareInterface>
      <mechanicalReduction>1.0</mechanicalReduction>
    </actuator>
  </transmission>
  <transmission name="r_shoulder_yaw_trans">
    <type>transmission_interface/SimpleTransmission</type>
    <joint name="r_shoulder_yaw">
      <hardwareInterface>EffortJointInterface</hardwareInterface>
    </joint>
    <actuator name="r_shoulder_yaw_motor">
      <hardwareInterface>EffortJointInterface</hardwareInterface>
      <mechanicalReduction>1.0</mechanicalReduction>
    </actuator>
  </transmission>
  <transmission name="r_elbow_pitch_trans">
    <type>transmission_interface/SimpleTransmission</type>
    <joint name="r_elbow_pitch">
      <hardwareInterface>EffortJointInterface</hardwareInterface>
    </joint>
    <actuator name="r_elbow_pitch_motor">
      <hardwareInterface>EffortJointInterface</hardwareInterface>
      <mechanicalReduction>1.0</mechanicalReduction>
    </actuator>
  </transmission>
  <transmission name="r_wrist_yaw_trans">
    <type>transmission_interface/SimpleTransmission</type>
    <joint name="r_wrist_yaw">
      <hardwareInterface>EffortJointInterface</hardwareInterface>
    </joint>
    <actuator name="r_wrist_yaw_motor">
      <hardwareInterface>EffortJointInterface</hardwareInterface>
      <mechanicalReduction>1.0</mechanicalReduction>
    </actuator>
  </transmission>
  <transmission name="r_wrist_pitch_trans">
    <type>transmission_interface/SimpleTransmission</type>
    <joint name="r_wrist_pitch">
      <hardwareInterface>EffortJointInterface</hardwareInterface>
    </joint>
    <actuator name="r_wrist_pitch_motor">
      <hardwareInterface>EffortJointInterface</hardwareInterface>
      <mechanicalReduction>1.0</mechanicalReduction>
    </actuator>
  </transmission>
  <!--****************
    **** GAZEBO ****
    ****************-->
  <!-- Import all Gazebo-customization elements, including Gazebo colors -->
  <!-- ros_control plugin -->
  <gazebo>
    <plugin filename="libgazebo_ros_control.so" name="gazebo_ros_control">
      <robotNamespace>/teo</robotNamespace>
    </plugin>
  </gazebo>
  <!-- ############### -->
  <!-- # TORSO LINKS # -->
  <!-- ############### -->
  <!-- ############## -->
  <!-- # LEGS LINKS # -->
  <!-- ############## -->
  <!-- ############## -->
  <!-- # ARMS LINKS # -->
  <!-- ############## -->
  <!-- Sensors -->
  <gazebo reference="waist_yaw_link">
    <mu1>0.9</mu1>
    <mu2>0.9</mu2>
    <material>Gazebo/White</material>
  </gazebo>
  <gazebo reference="waist_pitch_link">
    <mu1>0.9</mu1>
    <mu2>0.9</mu2>
    <material>Gazebo/White</material>
  </gazebo>
  <!-- 		<gazebo reference="waist">
			<mu1>0.9</mu1>
			<mu2>0.9</mu2>
			<material>Gazebo/White</material>
		</gazebo> -->
  <gazebo reference="l_hip_roll_link">
    <mu1>0.9</mu1>
    <mu2>0.9</mu2>
    <material>Gazebo/White</material>
  </gazebo>
  <gazebo reference="l_hip_yaw_link">
    <mu1>0.9</mu1>
    <mu2>0.9</mu2>
    <material>Gazebo/White</material>
  </gazebo>
  <gazebo reference="l_femur_link">
    <mu1>0.9</mu1>
    <mu2>0.9</mu2>
    <material>Gazebo/White</material>
  </gazebo>
  <gazebo reference="l_tibia_link">
    <mu1>0.9</mu1>
    <mu2>0.9</mu2>
    <material>Gazebo/White</material>
  </gazebo>
  <gazebo reference="l_ankle_pitch_link">
    <mu1>0.9</mu1>
    <mu2>0.9</mu2>
    <material>Gazebo/White</material>
  </gazebo>
  <gazebo reference="l_astragalus_link">
    <kp>1000000.0</kp>
    <kd>100.0</kd>
    <mu1>1.0</mu1>
    <mu2>1.0</mu2>
    <fdir1>0 0 1</fdir1>
    <maxVel>1.0</maxVel>
    <minDepth>0.00</minDepth>
    <implicitSpringDamper>1</implicitSpringDamper>
    <material>Gazebo/White</material>
  </gazebo>
  <gazebo reference="l_sole">
    <mu1>0.9</mu1>
    <mu2>0.9</mu2>
    <fdir1>1 0 0</fdir1>
    <maxVel>1.0</maxVel>
    <minDepth>0.003</minDepth>
    <material>Gazebo/White</material>
  </gazebo>
  <gazebo reference="r_hip_roll_link">
    <mu1>0.9</mu1>
    <mu2>0.9</mu2>
    <material>Gazebo/White</material>
  </gazebo>
  <gazebo reference="r_hip_yaw_link">
    <mu1>0.9</mu1>
    <mu2>0.9</mu2>
    <material>Gazebo/White</material>
  </gazebo>
  <gazebo reference="r_femur_link">
    <mu1>0.9</mu1>
    <mu2>0.9</mu2>
    <material>Gazebo/White</material>
  </gazebo>
  <gazebo reference="r_tibia_link">
    <mu1>0.9</mu1>
    <mu2>0.9</mu2>
    <material>Gazebo/White</material>
  </gazebo>
  <gazebo reference="r_ankle_pitch_link">
    <mu1>0.9</mu1>
    <mu2>0.9</mu2>
    <material>Gazebo/White</material>
  </gazebo>
  <gazebo reference="r_astragalus_link">
    <kp>1000000.0</kp>
    <kd>100.0</kd>
    <mu1>1.0</mu1>
    <mu2>1.0</mu2>
    <fdir1>0 0 1</fdir1>
    <maxVel>1.0</maxVel>
    <minDepth>0.00</minDepth>
    <implicitSpringDamper>1</implicitSpringDamper>
    <material>Gazebo/White</material>
  </gazebo>
  <gazebo reference="r_sole">
    <mu1>0.9</mu1>
    <mu2>0.9</mu2>
    <fdir1>1 0 0</fdir1>
    <maxVel>1.0</maxVel>
    <minDepth>0.003</minDepth>
    <material>Gazebo/White</material>
  </gazebo>
  <gazebo reference="l_shoulder_pitch_link">
    <mu1>0.9</mu1>
    <mu2>0.9</mu2>
    <material>Gazebo/White</material>
  </gazebo>
  <gazebo reference="l_shoulder_roll_link">
    <mu1>0.9</mu1>
    <mu2>0.9</mu2>
    <material>Gazebo/White</material>
  </gazebo>
  <gazebo reference="l_shoulder_yaw_link">
    <mu1>0.9</mu1>
    <mu2>0.9</mu2>
    <material>Gazebo/White</material>
  </gazebo>
  <gazebo reference="l_elbow_pitch_link">
    <mu1>0.9</mu1>
    <mu2>0.9</mu2>
    <material>Gazebo/White</material>
  </gazebo>
  <gazebo reference="l_wrist_yaw_link">
    <mu1>0.9</mu1>
    <mu2>0.9</mu2>
    <material>Gazebo/White</material>
  </gazebo>
  <gazebo reference="l_wrist_pitch_link">
    <mu1>0.9</mu1>
    <mu2>0.9</mu2>
    <material>Gazebo/White</material>
  </gazebo>
  <gazebo reference="r_shoulder_pitch_link">
    <mu1>0.9</mu1>
    <mu2>0.9</mu2>
    <material>Gazebo/White</material>
  </gazebo>
  <gazebo reference="r_shoulder_roll_link">
    <mu1>0.9</mu1>
    <mu2>0.9</mu2>
    <material>Gazebo/White</material>
  </gazebo>
  <gazebo reference="r_shoulder_yaw_link">
    <mu1>0.9</mu1>
    <mu2>0.9</mu2>
    <material>Gazebo/White</material>
  </gazebo>
  <gazebo reference="r_elbow_pitch_link">
    <mu1>0.9</mu1>
    <mu2>0.9</mu2>
    <material>Gazebo/White</material>
  </gazebo>
  <gazebo reference="r_wrist_yaw_link">
    <mu1>0.9</mu1>
    <mu2>0.9</mu2>
    <material>Gazebo/White</material>
  </gazebo>
  <gazebo reference="r_wrist_pitch_link">
    <mu1>0.9</mu1>
    <mu2>0.9</mu2>
    <material>Gazebo/White</material>
  </gazebo>
  <!-- TEO visualization -->
  <!--xacro:if value="$(arg simple_vis)">
    <xacro:include filename="$(find teo_description)/urdf/simple_visual.xacro" />
  </xacro:if-->
  <!--xacro:unless complete_vis="$(arg complete_vis)">
    <xacro:include filename="$(find teo_description)/urdf/visualization.xacro" />
  </xacro:unless-->
  <!--xacro:include filename="$(find teo_description)/urdf/visual.xacro" /-->
  <material name="teoGray">
    <color rgba="0.6 0.6 0.6 1.0"/>
  </material>
  <material name="teoBlue">
    <color rgba="0.0 0.0 1.0 1.0"/>
  </material>
  <material name="teoBlack">
    <color rgba="0.0 0.0 0.0 1.0"/>
  </material>
</robot>

